/ext3/miniconda3/lib/python3.8/site-packages/scipy/__init__.py:138: UserWarning: A NumPy version >=1.16.5 and <1.23.0 is required for this version of SciPy (detected version 1.23.3)
  warnings.warn(f"A NumPy version >={np_minversion} and <{np_maxversion} is required for this version of "
/scratch/cg3306/climate/climate_research/data/load.py:41: RuntimeWarning: Failed to open Zarr store with consolidated metadata, falling back to try reading non-consolidated metadata. This is typically much slower for opening a dataset. To silence this warning, consider:
1. Consolidating metadata in this existing store with zarr.consolidate_metadata().
2. Explicitly setting consolidated=False, to avoid trying to read consolidate metadata, or
3. Explicitly setting consolidated=True, to raise an error in this case instead of falling back to try reading non-consolidated metadata.
  ds_zarr= xr.open_zarr(data_address)
Traceback (most recent call last):
  File "/ext3/miniconda3/lib/python3.8/site-packages/xarray/backends/zarr.py", line 384, in open_group
    zarr_group = zarr.open_consolidated(store, **open_kwargs)
  File "/home/cg3306/.local/lib/python3.8/site-packages/zarr/convenience.py", line 1178, in open_consolidated
    meta_store = ConsolidatedMetadataStore(store, metadata_key=metadata_key)
  File "/home/cg3306/.local/lib/python3.8/site-packages/zarr/storage.py", line 2680, in __init__
    meta = json_loads(store[metadata_key])
  File "/home/cg3306/.local/lib/python3.8/site-packages/zarr/storage.py", line 826, in __getitem__
    raise KeyError(key)
KeyError: '.zmetadata'

During handling of the above exception, another exception occurred:

Traceback (most recent call last):
  File "run/scalars.py", line 59, in <module>
    main()
  File "run/scalars.py", line 11, in main
    generator,= get_data(args,half_spread = 0, torch_flag = False, data_loaders = True,groups = ('train',))
  File "/scratch/cg3306/climate/climate_research/data/load.py", line 98, in get_data
    dsets = load_dataset(args,torch_flag = torch_flag,**kwargs)
  File "/scratch/cg3306/climate/climate_research/data/load.py", line 83, in load_dataset
    _args,_kwargs = dataset_arguments(args,**kwargs)
  File "/scratch/cg3306/climate/climate_research/data/load.py", line 46, in dataset_arguments
    ds_zarr = load_xr_dataset(args)
  File "/scratch/cg3306/climate/climate_research/data/load.py", line 41, in load_xr_dataset
    ds_zarr= xr.open_zarr(data_address)
  File "/ext3/miniconda3/lib/python3.8/site-packages/xarray/backends/zarr.py", line 789, in open_zarr
    ds = open_dataset(
  File "/ext3/miniconda3/lib/python3.8/site-packages/xarray/backends/api.py", line 531, in open_dataset
    backend_ds = backend.open_dataset(
  File "/ext3/miniconda3/lib/python3.8/site-packages/xarray/backends/zarr.py", line 837, in open_dataset
    store = ZarrStore.open_group(
  File "/ext3/miniconda3/lib/python3.8/site-packages/xarray/backends/zarr.py", line 401, in open_group
    zarr_group = zarr.open_group(store, **open_kwargs)
  File "/home/cg3306/.local/lib/python3.8/site-packages/zarr/hierarchy.py", line 1166, in open_group
    raise GroupNotFoundError(path)
zarr.errors.GroupNotFoundError: group not found at path ''
